<!DOCTYPE html>
<html>
<head>

<link rel="icon" href="favicon.ico" type="image/x-icon"/>
<link rel="shortcut icon" href="favicon.ico" type="image/x-icon">
<title>Nico Brailovsky's blog</title>

<meta charset="UTF-8">
<meta name="viewport" content="width=device-width, initial-scale=1">
<link rel="stylesheet" href="/style.css">
</head>

<body>

<div id="siteheader">
<h1>Nico Brailovsky's blog</h1>

<div class="nav tabs is-full">
  <a class="is-center" href="/">Home</a>
  <a class="is-center" href="/blog/index.html">Blog</a>
  <a class="is-center"
     href="https://github.com/search?type=code&q=repo%3Anicolasbrailo%2Fnicolasbrailo.github.io%20sitesearch"
     onclick="togglesearch(); return false">Site search</a>
  <a class="is-center" href="/blog/history.html">Archive</a>
  <a class="is-center" href="/series.html">Series</a>
  <a class="is-center" href="/projects.html">Projects</a>
  <a class="is-center" href="/about.html">About</a>
</div>

<div id="sitesearch" class="nav tabs is-full is-hidden">
  <input type="text" id="sitesearch_q"/>
  <button onclick="dosearch()">Search</button>
</div>

</div>

<div id="content" class="language-clike">
<h1>C++ exceptions under the hood 9: catching our first exception<a name="cexceptionsunderthehood9catchingourfirstexception"></a></h1>
<p>We finished last chapter on the series about C++ exceptions by adding a personality function that _Unwind_ was able to call and then analyzing the parameters that the personality function receives. Now it's time to begin adding some real behavior to __gxx_personality_v0: when __gxx_personality_v0 is called we should say "yes, this stack frame can indeed handle this exception".</p>
<p>We have been building up to this point quite a bit: the time where we can implement for the first time a personality function capable of detecting when an exception is thrown, and then saying "yes, I will handle this exception". For that we had to learn how the two-phase lookup work, so we can now reimplement our personality function and our throw test file:</p>
<pre lang="c++"><code class="language-c++" lang="c++">#include <stdio.h>
#include "throw.h"
struct Fake_Exception {};
void raise() {
    throw Exception();
}
void try_but_dont_catch() {
    try {
        raise();
    } catch(Fake_Exception&amp;) {
        printf("Caught a Fake_Exception!\n");
    }
    printf("try_but_dont_catch handled the exception\n");
}
void catchit() {
    try {
        try_but_dont_catch();
    } catch(Exception&amp;) {
        printf("Caught an Exception!\n");
    }
    printf("catchit handled the exception\n");
}
extern "C" {
    void seppuku() {
        catchit();
    }
}
</code></pre>
<p>And our personality function:</p>
<pre lang="c++"><code class="language-c++" lang="c++">_Unwind_Reason_Code __gxx_personality_v0 (
                     int version, _Unwind_Action actions, uint64_t exceptionClass,
                     _Unwind_Exception<em> unwind_exception, _Unwind_Context</em> context)
{
    if (actions &amp; _UA_SEARCH_PHASE)
    {
        printf("Personality function, lookup phase\n");
        return _URC_HANDLER_FOUND;
    } else if (actions &amp; _UA_CLEANUP_PHASE) {
        printf("Personality function, cleanup\n");
        return _URC_INSTALL_CONTEXT;
    } else {
        printf("Personality function, error\n");
        return _URC_FATAL_PHASE1_ERROR;
    }
}
</code></pre>
<p>Note: You can download the full sourcecode for this project <a href="https://github.com/nicolasbrailo/cpp_exception_handling_abi/tree/master/abi_v03">in my github repo</a>.</p>
<p>Let's run it, see what happens:</p>
<pre lang="c++"><code class="language-c++" lang="c++">alloc ex 1
__cxa_throw called
Personality function, lookup phase
Personality function, cleanup
try_but_dont_catch handled the exception
catchit handled the exception
</code></pre>
<p>It works, but something is missing: the catch inside the catch/try block is not being executed! This is happening because the personality function tells Unwind to "install a context" (ie to resume execution) but it never says which context. In this case it's probably resuming executing from after the landing pad, but I'd bet this is actually undefined behavior. We'll see next time how we can specify we want to resume executing from a specific landing pad using the information available on .gcc_except_table (our old friend, the LSDA).</p>
<hr />
<p>Post by Nico Brailovsky @ 2013-04-02 -
    <a href="/blog/2013/0402_Cexceptionsunderthehood9catchingourfirstexception.html">Permalink</a> -
    <a href="https://github.com/nicolasbrailo/nicolasbrailo.github.io/issues/new?title=Comment@/blog_md/2013/0402_Cexceptionsunderthehood9catchingourfirstexception.md&amp;body=I%20have%20a%20comment!">Leave a comment</a></p>
</div>

<div id="sitefooter">
Page generated 2024-02-18
</div>

<script src="/search.js"></script>
<script src="/codehighlight.js"></script>

</body>
</html>
